Workbook

Sheet HYPOTHESES
A1: PRÉVISIONS FINANCIÈRES SUR 5 ANS : HYPOTHÈSES
A2: Référentiel : SYSCOHADA révisé (AUDCIF 2017) et CGI de Côte d'Ivoire. Montants en FCFA.
A3: Mode d'emploi : saisir uniquement les cellules sur fond JAUNE (texte bleu) de cet onglet et de l'onglet INVEST ET FINANCEMENT. Tout le reste (balances, bilan, compte de résultat, TFT) se recalcule automatiquement.
A4: Nom de l'entité | C4: MON ENTREPRISE
A5: Dernier exercice réel (année de base) | C5: 2024 | I5: Balance réelle reprise de l'onglet « 2025 » du fichier BALANCES_ET_PREVISIONS_TEST (soldes de clôture 31/12/2024).
A7: Rubrique | B7: Réf. / compte | C7: ="Réel "&$C$5 -> Réel 2024 | D7: =$C$5+1 -> 2025 | E7: =$C$5+2 -> 2026 | F7: =$C$5+3 -> 2027 | G7: =$C$5+4 -> 2028 | H7: =$C$5+5 -> 2029 | I7: Commentaire / source
A8: 1. ACTIVITÉ
A9: Taux de croissance du chiffre d'affaires | B9: % | D9: 0.07 | E9: 0.05 | F9: 0.05 | G9: 0.05 | H9: 0.05 | I9: Hypothèse à ajuster selon le carnet de commandes / marchés attendus.
A10: Taux de TVA | B10: % | D10: 0.18 | E10: 0.18 | F10: 0.18 | G10: 0.18 | H10: 0.18 | I10: CGI CI art. 359 : taux normal 18 %.
A11: Revenus financiers | B11: 77 | C11: =SUMIFS('BALANCE 2024'!$I:$I,'BALANCE 2024'!$C:$C,"TK") -> 848594 | D11: 848594 | E11: 848594 | F11: 848594 | G11: 848594 | H11: 848594 | I11: Défaut : niveau réel de l'année de base.
A12: 2. CHARGES D'EXPLOITATION EN % DU CHIFFRE D'AFFAIRES (clé de répartition)
A13: Achats et autres approvisionnements | B13: 604-605-608 | C13: =IF(SUMIFS('BALANCE 2024'!$I:$I,'BALANCE 2024'!$C:$C,"TC")=0,0,SUMIFS('BALANCE 2024'!$H:$H,'BALANCE 2024'!$C:$C,"RE")/SUMIFS('BALANCE 2024'!$I:$I,'BALANCE 2024'!$C:$C,"TC")) -> 0.39676301 | D13: 0.3968 | E13: 0.3968 | F13: 0.3968 | G13: 0.3968 | H13: 0.3968 | I13: Défaut : ratio réel de l'année de base. Chaque compte de détail est ensuite réparti selon sa part dans la balance de base.
A14: Transports | B14: 61 | C14: =IF(SUMIFS('BALANCE 2024'!$I:$I,'BALANCE 2024'!$C:$C,"TC")=0,0,SUMIFS('BALANCE 2024'!$H:$H,'BALANCE 2024'!$C:$C,"RG")/SUMIFS('BALANCE 2024'!$I:$I,'BALANCE 2024'!$C:$C,"TC")) -> 0.0054492903 | D14: 0.0054 | E14: 0.0054 | F14: 0.0054 | G14: 0.0054 | H14: 0.0054 | I14: Défaut : ratio réel de l'année de base. Chaque compte de détail est ensuite réparti selon sa part dans la balance de base.
A15: Services extérieurs | B15: 62-63 | C15: =IF(SUMIFS('BALANCE 2024'!$I:$I,'BALANCE 2024'!$C:$C,"TC")=0,0,SUMIFS('BALANCE 2024'!$H:$H,'BALANCE 2024'!$C:$C,"RH")/SUMIFS('BALANCE 2024'!$I:$I,'BALANCE 2024'!$C:$C,"TC")) -> 0.15230388 | D15: 0.1523 | E15: 0.1523 | F15: 0.1523 | G15: 0.1523 | H15: 0.1523 | I15: Défaut : ratio réel de l'année de base. Chaque compte de détail est ensuite réparti selon sa part dans la balance de base.
A16: Impôts et taxes | B16: 64 | C16: =IF(SUMIFS('BALANCE 2024'!$I:$I,'BALANCE 2024'!$C:$C,"TC")=0,0,SUMIFS('BALANCE 2024'!$H:$H,'BALANCE 2024'!$C:$C,"RI")/SUMIFS('BALANCE 2024'!$I:$I,'BALANCE 2024'!$C:$C,"TC")) -> 0.021211275 | D16: 0.0212 | E16: 0.0212 | F16: 0.0212 | G16: 0.0212 | H16: 0.0212 | I16: Défaut : ratio réel de l'année de base. Chaque compte de détail est ensuite réparti selon sa part dans la balance de base.
A17: Autres charges | B17: 65 | C17: =IF(SUMIFS('BALANCE 2024'!$I:$I,'BALANCE 2024'!$C:$C,"TC")=0,0,SUMIFS('BALANCE 2024'!$H:$H,'BALANCE 2024'!$C:$C,"RJ")/SUMIFS('BALANCE 2024'!$I:$I,'BALANCE 2024'!$C:$C,"TC")) -> 0.0018782894 | D17: 0.0019 | E17: 0.0019 | F17: 0.0019 | G17: 0.0019 | H17: 0.0019 | I17: Défaut : ratio réel de l'année de base. Chaque compte de détail est ensuite réparti selon sa part dans la balance de base.
A18: Charges de personnel | B18: 66 | C18: =IF(SUMIFS('BALANCE 2024'!$I:$I,'BALANCE 2024'!$C:$C,"TC")=0,0,SUMIFS('BALANCE 2024'!$H:$H,'BALANCE 2024'!$C:$C,"RK")/SUMIFS('BALANCE 2024'!$I:$I,'BALANCE 2024'!$C:$C,"TC")) -> 0.15124319 | D18: 0.1512 | E18: 0.1512 | F18: 0.1512 | G18: 0.1512 | H18: 0.1512 | I18: Défaut : ratio réel de l'année de base. Chaque compte de détail est ensuite réparti selon sa part dans la balance de base.
A19: 3. PROVISIONS
A20: Dotation aux provisions pour retraite (IFC) | B20: 691 / 196 | D20: 6059296 | E20: 6059296 | F20: 6059296 | G20: 6059296 | H20: 6059296 | I20: Défaut : dotation réelle de l'année de base.
A21: 4. BESOIN EN FONDS DE ROULEMENT
A22: Délai de paiement clients (jours de CA TTC) | B22: 411 | C22: =IF(C42=0,0,SUMIFS('BALANCE 2024'!$H:$H,'BALANCE 2024'!$C:$C,"BI")/(C42*(1+D10))*360) -> 196.82717 | D22: 190 | E22: 197 | F22: 197 | G22: 197 | H22: 197 | I22: Défaut : délai réel de l'année de base. Attention : délai légal max 60 j (AUDCG / directive UEMOA).
A23: Délai de paiement fournisseurs (jours d'achats et services TTC) | B23: 401 | C23: =IF(C49=0,0,SUMIFS('BALANCE 2024'!$I:$I,'BALANCE 2024'!$C:$C,"DJ")/(C49*(1+D10))*360) -> 57.251162 | D23: 57 | E23: 57 | F23: 57 | G23: 57 | H23: 57 | I23: Base : achats (60) + transports (61) + services extérieurs (62-63).
A24: Délai de paiement des fournisseurs d'investissement (jours d'acquisitions HT) | B24: 4812 | C24: =IF('INVEST ET FINANCEMENT'!C41=0,0,SUMIFS('BALANCE 2024'!$I:$I,'BALANCE 2024'!$C:$C,"DH")/'INVEST ET FINANCEMENT'!C41*360) -> 131.098 | D24: 131 | E24: 131 | F24: 131 | G24: 131 | H24: 131 | I24: Dette de l'année sur les acquisitions de l'année = acquisitions x délai / 360. Défaut : délai réel 2024 (132,9 M / 364,9 M d'acquisitions).
A25: Règlement de la dette fournisseurs d'investissement du 31/12 de base (% de l'encours) | B25: 4812 | D25: 0.6 | E25: 0.4 | F25: 0 | G25: 0 | H25: 0 | I25: Échéancier de l'encours 2024 (132,9 M) : non soldé en 2025. Le cumul ne doit pas dépasser 100 %.
A26: Encours de base restant dû au 31/12 | B26: 4812 | C26: =ROUND(SUMIFS('BALANCE 2024'!$I:$I,'BALANCE 2024'!$C:$C,"DH"),0) -> 132896547 | D26: =ROUND($C26*MAX(0,1-SUM($D25:D25)),0) -> 53158619 | E26: =ROUND($C26*MAX(0,1-SUM($D25:E25)),0) -> 0 | F26: =ROUND($C26*MAX(0,1-SUM($D25:F25)),0) -> 0 | G26: =ROUND($C26*MAX(0,1-SUM($D25:G25)),0) -> 0 | H26: =ROUND($C26*MAX(0,1-SUM($D25:H25)),0) -> 0
A27: Dette sur acquisitions de l'année | B27: 4812 | D27: =ROUND('INVEST ET FINANCEMENT'!D41*D24/360,0) -> 6012616 | E27: =ROUND('INVEST ET FINANCEMENT'!E41*E24/360,0) -> 12736111 | F27: =ROUND('INVEST ET FINANCEMENT'!F41*F24/360,0) -> 12736111 | G27: =ROUND('INVEST ET FINANCEMENT'!G41*G24/360,0) -> 27291667 | H27: =ROUND('INVEST ET FINANCEMENT'!H41*H24/360,0) -> 12736111
A28: Dette fournisseurs d'investissement au 31/12 (poste DH du bilan) | B28: 4812 | C28: =ROUND(C26,0) -> 132896547 | D28: =ROUND(D26+D27,0) -> 59171235 | E28: =ROUND(E26+E27,0) -> 12736111 | F28: =ROUND(F26+F27,0) -> 12736111 | G28: =ROUND(G26+G27,0) -> 27291667 | H28: =ROUND(H26+H27,0) -> 12736111
A29: Part des sorties de banque affectée à l'approvisionnement de la caisse (virement de fonds 585) | B29: 571 / 585 | D29: 0.2 | E29: 0.2 | F29: 0.2 | G29: 0.2 | H29: 0.2 | I29: Appro caisse = % x mouvements crédit du 521. Seule entrée en caisse (D 585 / C 521 puis D 571 / C 585). Créances clients encaissées par chèque ou virement. Soldes banque et caisse inchangés.
A30: Décaissements en espèces (% des approvisionnements de caisse de l'année) | B30: 571 | D30: 0.99 | E30: 0.99 | F30: 0.99 | G30: 0.99 | H30: 0.99 | I30: Moins de 100 % : la caisse augmente ; plus de 100 % : elle diminue. Solde de caisse = ouverture + appro x (1 - %). La banque absorbe l'écart.
A31: Ajustement des autres dettes (+ augmentation / - diminution de l'année) | B31: 4712 | D31: 0 | E31: 0 | F31: 0 | G31: 0 | H31: 0 | I31: Mouvement net saisi librement (créditeurs divers). Si le solde cumulé devient débiteur, il passe en autres créances (BJ).
I32: Les autres dettes fiscales et sociales évoluent comme leur charge de référence (66, 64) ; la TVA sur travaux en attente (4433, exigible à l'encaissement) suit les créances clients.
A33: 5. FISCALITÉ (Côte d'Ivoire)
A34: Taux de l'impôt sur les bénéfices | B34: % | D34: 0.25 | E34: 0.25 | F34: 0.25 | G34: 0.25 | H34: 0.25 | I34: CGI art. 51 : 25 %.
A35: Taux de l'IMF (sur CA TTC) | B35: % | D35: 0.005 | E35: 0.005 | F35: 0.005 | G35: 0.005 | H35: 0.005 | I35: CGI art. 39 : 0,5 % du CA TTC.
A36: IMF minimum | B36: FCFA | D36: 3000000 | E36: 3000000 | F36: 3000000 | G36: 3000000 | H36: 3000000 | I36: CGI art. 39.
A37: IMF maximum | B37: FCFA | D37: 35000000 | E37: 35000000 | F37: 35000000 | G37: 35000000 | H37: 35000000 | I37: CGI art. 39.
A38: Réintégrations fiscales nettes (+) / déductions (-) | B38: FCFA | D38: 0 | E38: 0 | F38: 0 | G38: 0 | H38: 0 | I38: Charges non déductibles (amendes, charges sans FNE, etc.) issues du tableau de passage.
A39: Dotation à la réserve légale (% du bénéfice) | B39: % | D39: 0.1 | E39: 0.1 | F39: 0.1 | G39: 0.1 | H39: 0.1 | I39: AUSCGIE art. 346 : 10 % jusqu'à 20 % du capital.
A40: Plafond de la réserve légale (% du capital) | B40: % | D40: 0.2 | E40: 0.2 | F40: 0.2 | G40: 0.2 | H40: 0.2 | I40: AUSCGIE art. 346.
A41: 6. CALCULS DU RÉSULTAT ET DE L'IMPÔT (ne pas modifier)
...

Sheet INVEST ET FINANCEMENT
A1: HYPOTHÈSES D'INVESTISSEMENT ET DE FINANCEMENT
A2: Plan d'investissement, amortissements, endettement et plan de financement. Montants en FCFA.
A3: Mode d'emploi : saisir uniquement les cellules sur fond JAUNE (texte bleu). Les sections B, D et E se calculent automatiquement.
A4: ="Entité : "&HYPOTHESES!$C$4 -> Entité : MON ENTREPRISE
A7: Rubrique | B7: Réf. / compte | C7: ="Réel "&HYPOTHESES!$C$5 -> Réel 2024 | D7: =HYPOTHESES!$C$5+1 -> 2025 | E7: =HYPOTHESES!$C$5+2 -> 2026 | F7: =HYPOTHESES!$C$5+3 -> 2027 | G7: =HYPOTHESES!$C$5+4 -> 2028 | H7: =HYPOTHESES!$C$5+5 -> 2029 | I7: Commentaire / source
A8: A. PLAN D'INVESTISSEMENT (montants HT, acquisitions supposées au 1er janvier)
A9: Aménagements, agencements, installations | B9: 2341 / 2834 | C9: 0 | D9: 0 | E9: 0 | F9: 0 | G9: 0 | H9: 0 | I9: Colonne réel : acquisitions de l'année de base (mouvements débit 2024, hors location-acquisition 2456).
A10: Matériel et outillage industriel | B10: 2411 / 2841 | C10: 294528381 | D10: 0 | E10: 30000000 | F10: 30000000 | G10: 30000000 | H10: 30000000 | I10: Colonne réel : acquisitions de l'année de base (mouvements débit 2024, hors location-acquisition 2456).
A11: Matériel de bureau et informatique | B11: 2442 / 2844 | C11: 14513941 | D11: 930000 | E11: 5000000 | F11: 5000000 | G11: 5000000 | H11: 5000000 | I11: Colonne réel : acquisitions de l'année de base (mouvements débit 2024, hors location-acquisition 2456).
A12: Matériel de transport | B12: 2451 / 2845 | C12: 55896547 | D12: 15593220 | E12: 0 | F12: 0 | G12: 40000000 | H12: 0 | I12: Colonne réel : acquisitions de l'année de base (mouvements débit 2024, hors location-acquisition 2456).
A13: Nouveaux dépôts et cautionnements versés | B13: 275 | D13: 0 | E13: 0 | F13: 0 | G13: 0 | H13: 0
A14: Durée d'amortissement linéaire (années)
A15: Aménagements, agencements, installations | C15: 10 | I15: Durée d'utilité retenue (AUDCIF art. 45), fixée par l'entité.
A16: Matériel et outillage industriel | C16: 5 | I16: Durée d'utilité retenue (AUDCIF art. 45), fixée par l'entité.
A17: Matériel de bureau et informatique | C17: 2 | I17: Durée d'utilité retenue (AUDCIF art. 45), fixée par l'entité.
A18: Matériel de transport | C18: 3 | I18: Durée d'utilité retenue (AUDCIF art. 45), fixée par l'entité.
A19: Dotation annuelle sur les immobilisations existantes (plafonnée à la VNC restante)
A20: Aménagements, agencements, installations | B20: 681 | D20: 19282845 | E20: 19282845 | F20: 19282845 | G20: 19282845 | H20: 19282845 | I20: Défaut : dotation réelle de l'année de base.
A21: Matériel et outillage industriel | B21: 681 | D21: 28205053 | E21: 44854932 | F21: 44854932 | G21: 44854932 | H21: 44854932 | I21: Défaut : dotation réelle de l'année de base.
A22: Matériel de bureau et informatique | B22: 681 | D22: 4934884 | E22: 4934884 | F22: 4934884 | G22: 4934884 | H22: 4934884 | I22: Défaut : dotation réelle de l'année de base.
A23: Matériel de transport | B23: 681 | D23: 13760638 | E23: 10760638 | F23: 10760638 | G23: 10760638 | H23: 10760638 | I23: Défaut : dotation réelle de l'année de base.
A24: VNC au 31/12 de base des immo. existantes : aménagements, agencements, installations | B24: 2341 / 2834 | C24: 61665016 | I24: Brut moins amortissements de la balance de base.
A25: VNC au 31/12 de base des immo. existantes : matériel et outillage industriel | B25: 2411 / 2841 | C25: 257861504 | I25: Brut moins amortissements de la balance de base.
A26: VNC au 31/12 de base des immo. existantes : matériel de bureau et informatique | B26: 2442 / 2844 | C26: 9579057 | I26: Brut moins amortissements de la balance de base.
A27: VNC au 31/12 de base des immo. existantes : matériel de transport | B27: 2451 / 2845 | C27: 73755603 | I27: Brut moins amortissements de la balance de base.
A28: B. AMORTISSEMENTS ET TABLEAU DES IMMOBILISATIONS CORPORELLES (calculé)
A29: Dotation sur existant : aménagements, agencements, installations | B29: 681 | D29: =ROUND(MIN(D20,$C24),0) -> 19282845 | E29: =ROUND(MIN(E20,$C24-SUM($D29:D29)),0) -> 19282845 | F29: =ROUND(MIN(F20,$C24-SUM($D29:E29)),0) -> 19282845 | G29: =ROUND(MIN(G20,$C24-SUM($D29:F29)),0) -> 3816481 | H29: =ROUND(MIN(H20,$C24-SUM($D29:G29)),0) -> 0
A30: Dotation sur acquisitions nouvelles : aménagements, agencements, installations | B30: 681 | D30: =ROUND(SUMPRODUCT($D9:D9/$C15*((D$7-$D$7:D$7)<$C15)),0) -> 0 | E30: =ROUND(SUMPRODUCT($D9:E9/$C15*((E$7-$D$7:E$7)<$C15)),0) -> 0 | F30: =ROUND(SUMPRODUCT($D9:F9/$C15*((F$7-$D$7:F$7)<$C15)),0) -> 0 | G30: =ROUND(SUMPRODUCT($D9:G9/$C15*((G$7-$D$7:G$7)<$C15)),0) -> 0 | H30: =ROUND(SUMPRODUCT($D9:H9/$C15*((H$7-$D$7:H$7)<$C15)),0) -> 0
A31: Dotation totale : aménagements, agencements, installations | B31: 681 | D31: =ROUND(D29+D30,0) -> 19282845 | E31: =ROUND(E29+E30,0) -> 19282845 | F31: =ROUND(F29+F30,0) -> 19282845 | G31: =ROUND(G29+G30,0) -> 3816481 | H31: =ROUND(H29+H30,0) -> 0
A32: Dotation sur existant : matériel et outillage industriel | B32: 681 | D32: =ROUND(MIN(D21,$C25),0) -> 28205053 | E32: =ROUND(MIN(E21,$C25-SUM($D32:D32)),0) -> 44854932 | F32: =ROUND(MIN(F21,$C25-SUM($D32:E32)),0) -> 44854932 | G32: =ROUND(MIN(G21,$C25-SUM($D32:F32)),0) -> 44854932 | H32: =ROUND(MIN(H21,$C25-SUM($D32:G32)),0) -> 44854932
A33: Dotation sur acquisitions nouvelles : matériel et outillage industriel | B33: 681 | D33: =ROUND(SUMPRODUCT($D10:D10/$C16*((D$7-$D$7:D$7)<$C16)),0) -> 0 | E33: =ROUND(SUMPRODUCT($D10:E10/$C16*((E$7-$D$7:E$7)<$C16)),0) -> 6000000 | F33: =ROUND(SUMPRODUCT($D10:F10/$C16*((F$7-$D$7:F$7)<$C16)),0) -> 12000000 | G33: =ROUND(SUMPRODUCT($D10:G10/$C16*((G$7-$D$7:G$7)<$C16)),0) -> 18000000 | H33: =ROUND(SUMPRODUCT($D10:H10/$C16*((H$7-$D$7:H$7)<$C16)),0) -> 24000000
A34: Dotation totale : matériel et outillage industriel | B34: 681 | D34: =ROUND(D32+D33,0) -> 28205053 | E34: =ROUND(E32+E33,0) -> 50854932 | F34: =ROUND(F32+F33,0) -> 56854932 | G34: =ROUND(G32+G33,0) -> 62854932 | H34: =ROUND(H32+H33,0) -> 68854932
A35: Dotation sur existant : matériel de bureau et informatique | B35: 681 | D35: =ROUND(MIN(D22,$C26),0) -> 4934884 | E35: =ROUND(MIN(E22,$C26-SUM($D35:D35)),0) -> 4644173 | F35: =ROUND(MIN(F22,$C26-SUM($D35:E35)),0) -> 0 | G35: =ROUND(MIN(G22,$C26-SUM($D35:F35)),0) -> 0 | H35: =ROUND(MIN(H22,$C26-SUM($D35:G35)),0) -> 0
A36: Dotation sur acquisitions nouvelles : matériel de bureau et informatique | B36: 681 | D36: =ROUND(SUMPRODUCT($D11:D11/$C17*((D$7-$D$7:D$7)<$C17)),0) -> 465000 | E36: =ROUND(SUMPRODUCT($D11:E11/$C17*((E$7-$D$7:E$7)<$C17)),0) -> 2965000 | F36: =ROUND(SUMPRODUCT($D11:F11/$C17*((F$7-$D$7:F$7)<$C17)),0) -> 5000000 | G36: =ROUND(SUMPRODUCT($D11:G11/$C17*((G$7-$D$7:G$7)<$C17)),0) -> 5000000 | H36: =ROUND(SUMPRODUCT($D11:H11/$C17*((H$7-$D$7:H$7)<$C17)),0) -> 5000000
A37: Dotation totale : matériel de bureau et informatique | B37: 681 | D37: =ROUND(D35+D36,0) -> 5399884 | E37: =ROUND(E35+E36,0) -> 7609173 | F37: =ROUND(F35+F36,0) -> 5000000 | G37: =ROUND(G35+G36,0) -> 5000000 | H37: =ROUND(H35+H36,0) -> 5000000
A38: Dotation sur existant : matériel de transport | B38: 681 | D38: =ROUND(MIN(D23,$C27),0) -> 13760638 | E38: =ROUND(MIN(E23,$C27-SUM($D38:D38)),0) -> 10760638 | F38: =ROUND(MIN(F23,$C27-SUM($D38:E38)),0) -> 10760638 | G38: =ROUND(MIN(G23,$C27-SUM($D38:F38)),0) -> 10760638 | H38: =ROUND(MIN(H23,$C27-SUM($D38:G38)),0) -> 10760638
A39: Dotation sur acquisitions nouvelles : matériel de transport | B39: 681 | D39: =ROUND(SUMPRODUCT($D12:D12/$C18*((D$7-$D$7:D$7)<$C18)),0) -> 5197740 | E39: =ROUND(SUMPRODUCT($D12:E12/$C18*((E$7-$D$7:E$7)<$C18)),0) -> 5197740 | F39: =ROUND(SUMPRODUCT($D12:F12/$C18*((F$7-$D$7:F$7)<$C18)),0) -> 5197740 | G39: =ROUND(SUMPRODUCT($D12:G12/$C18*((G$7-$D$7:G$7)<$C18)),0) -> 13333333 | H39: =ROUND(SUMPRODUCT($D12:H12/$C18*((H$7-$D$7:H$7)<$C18)),0) -> 13333333
A40: Dotation totale : matériel de transport | B40: 681 | D40: =ROUND(D38+D39,0) -> 18958378 | E40: =ROUND(E38+E39,0) -> 15958378 | F40: =ROUND(F38+F39,0) -> 15958378 | G40: =ROUND(G38+G39,0) -> 24093971 | H40: =ROUND(H38+H39,0) -> 24093971
A41: Total investissements corporels | C41: =ROUND(C9+C10+C11+C12,0) -> 364938869 | D41: =ROUND(D9+D10+D11+D12,0) -> 16523220 | E41: =ROUND(E9+E10+E11+E12,0) -> 35000000 | F41: =ROUND(F9+F10+F11+F12,0) -> 35000000 | G41: =ROUND(G9+G10+G11+G12,0) -> 75000000 | H41: =ROUND(H9+H10+H11+H12,0) -> 35000000
A42: Total dotations aux amortissements (681) | B42: 681 | C42: =ROUND(SUMIFS('BALANCE 2024'!$H:$H,'BALANCE 2024'!$A:$A,">=681000",'BALANCE 2024'!$A:$A,"<682000"),0) -> 79833299 | D42: =ROUND(D31+D34+D37+D40,0) -> 71846160 | E42: =ROUND(E31+E34+E37+E40,0) -> 93705328 | F42: =ROUND(F31+F34+F37+F40,0) -> 97096155 | G42: =ROUND(G31+G34+G37+G40,0) -> 95765384 | H42: =ROUND(H31+H34+H37+H40,0) -> 97948903
...

Sheet BALANCE 2024
A1: BALANCE GÉNÉRALE À 6 COLONNES : EXERCICE 2024 (RÉEL)
A2: Balance réelle reprise de l'onglet « 2025 » du fichier BALANCES_ET_PREVISIONS_TEST (ouverture 2024, mouvements 2024, clôture 2024).
D3: Soldes d'ouverture | F3: Mouvements de l'exercice | H3: Soldes de clôture | J3: Contrôle
A4: Compte | B4: Intitulé | C4: Poste | D4: Débit | E4: Crédit | F4: Débit | G4: Crédit | H4: Débit | I4: Crédit | J4: Ouv.+Mvts-Clôt.
A5: 101000 | B5: Capital social | C5: CA | D5: 0 | E5: 10000000 | F5: 0 | G5: 0 | H5: 0 | I5: 10000000 | J5: =(D5-E5)+(F5-G5)-(H5-I5) -> 0
A6: 111000 | B6: Réserve légale | C6: CF | D6: 0 | E6: 0 | F6: 0 | G6: 0 | H6: 0 | I6: 0 | J6: =(D6-E6)+(F6-G6)-(H6-I6) -> 0
A7: 121000 | B7: Report à nouveau | C7: CH | D7: 0 | E7: 654621364 | F7: 0 | G7: 119178487 | H7: 0 | I7: 773799851 | J7: =(D7-E7)+(F7-G7)-(H7-I7) -> 0
A8: 130100 | B8: Résultat en instance d'affectation : bénéfice | C8: R13 | D8: 0 | E8: 119178487 | F8: 119178487 | G8: 0 | H8: 0 | I8: 0 | J8: =(D8-E8)+(F8-G8)-(H8-I8) -> 0
A9: 162002 | B9: Emprunts auprès des établissements de crédit (BNI) | C9: DA | D9: 0 | E9: 0 | F9: 351341168 | G9: 391000000 | H9: 0 | I9: 39658832 | J9: =(D9-E9)+(F9-G9)-(H9-I9) -> 0
A10: 173060 | B10: Dettes de location-acquisition | C10: DB | D10: 0 | E10: 0 | F10: 18000000 | G10: 28619694 | H10: 0 | I10: 10619694 | J10: =(D10-E10)+(F10-G10)-(H10-I10) -> 0
A11: 196100 | B11: Provisions pour pensions et obligations similaires (IFC) | C11: DC | D11: 0 | E11: 15214600 | F11: 0 | G11: 6059296 | H11: 0 | I11: 21273896 | J11: =(D11-E11)+(F11-G11)-(H11-I11) -> 0
A12: 234100 | B12: Aménagements, agencements et installations techniques | C12: AL | D12: 103601492 | E12: 0 | F12: 0 | G12: 0 | H12: 103601492 | I12: 0 | J12: =(D12-E12)+(F12-G12)-(H12-I12) -> 0
A13: 241100 | B13: Matériel industriel | C13: AM | D13: 19316887 | E13: 0 | F13: 294528381 | G13: 0 | H13: 313845268 | I13: 0 | J13: =(D13-E13)+(F13-G13)-(H13-I13) -> 0
A14: 244100 | B14: Matériel de bureau | C14: AM | D14: 2050000 | E14: 0 | F14: 7256956 | G14: 0 | H14: 9306956 | I14: 0 | J14: =(D14-E14)+(F14-G14)-(H14-I14) -> 0
A15: 244200 | B15: Matériel informatique | C15: AM | D15: 5723474 | E15: 0 | F15: 7256985 | G15: 0 | H15: 12980459 | I15: 0 | J15: =(D15-E15)+(F15-G15)-(H15-I15) -> 0
A16: 245100 | B16: Matériel automobile | C16: AN | D16: 352148438 | E16: 0 | F16: 55896547 | G16: 0 | H16: 408044985 | I16: 0 | J16: =(D16-E16)+(F16-G16)-(H16-I16) -> 0
... A94: 895000 | B94: Impôt minimum forfaitaire (IMF) | C94: RS | D94: 0 | E94: 0 | F94: 0 | G94: 0 | H94: 0 | I94: 0 | J94: =(D94-E94)+(F94-G94)-(H94-I94) -> 0
B96: TOTAL BALANCE | D96: =SUM(D5:D94) -> 1308965390 | E96: =SUM(E5:E94) -> 1308965390 | F96: =SUM(F5:F94) -> 4378495087 | G96: =SUM(G5:G94) -> 4378495087 | H96: =SUM(H5:H94) -> 2342400758 | I96: =SUM(I5:I94) -> 2342400758 | J96: =SUM(J5:J94) -> 0
B97: Écart débit - crédit (doit être nul) | D97: =D96-E96 -> 0 | F97: =F96-G96 -> 0 | H97: =H96-I96 -> 0

Sheet BALANCE 2025
A1: BALANCE GÉNÉRALE À 6 COLONNES : EXERCICE 2025 (PRÉVISIONNEL)
A2: Ouverture = clôture de l'exercice précédent (classes 6 à 8 soldées, résultat N-1 en 13). Clôture calculée depuis les hypothèses ; mouvements = flux de l'exercice. Soldes après inventaire, avant écritures de clôture. Ne rien saisir.
D3: Soldes d'ouverture | F3: Mouvements de l'exercice | H3: Soldes de clôture | J3: Contrôle
A4: Compte | B4: Intitulé | C4: Poste | D4: Débit | E4: Crédit | F4: Débit | G4: Crédit | H4: Débit | I4: Crédit | J4: Ouv.+Mvts-Clôt.
A5: 101000 | B5: Capital social | C5: CA | D5: ='BALANCE 2024'!H5 -> 0 | E5: ='BALANCE 2024'!I5 -> 10000000 | F5: =ROUND('INVEST ET FINANCEMENT'!D$51,0)+(H5-I5)-(D5-E5) -> 0 | G5: =ROUND('INVEST ET FINANCEMENT'!D$51,0) -> 0 | H5: 0 | I5: =ROUND(E5+'INVEST ET FINANCEMENT'!D$51,0) -> 10000000 | J5: =(D5-E5)+(F5-G5)-(H5-I5) -> 0
A6: 111000 | B6: Réserve légale | C6: CF | D6: ='BALANCE 2024'!H6 -> 0 | E6: ='BALANCE 2024'!I6 -> 0 | F6: =ROUND(HYPOTHESES!D$58,0)+(H6-I6)-(D6-E6) -> 0 | G6: =ROUND(HYPOTHESES!D$58,0) -> 2000000 | H6: 0 | I6: =ROUND(E6+HYPOTHESES!D$58,0) -> 2000000 | J6: =(D6-E6)+(F6-G6)-(H6-I6) -> 0
A7: 121000 | B7: Report à nouveau | C7: CH | D7: ='BALANCE 2024'!H7 -> 0 | E7: ='BALANCE 2024'!I7 -> 773799851 | F7: =MAX(0,(H7-I7)-(D7-E7)) -> 0 | G7: =MAX(0,(D7-E7)-(H7-I7)) -> 70698877 | H7: =ROUND(MAX(0,-(E7-D7+HYPOTHESES!D$60)),0) -> 0 | I7: =ROUND(MAX(0,(E7-D7+HYPOTHESES!D$60)),0) -> 844498728 | J7: =(D7-E7)+(F7-G7)-(H7-I7) -> 0
A8: 130100 | B8: Résultat en instance d'affectation : bénéfice | C8: R13 | D8: =MAX(0,-(SUM('BALANCE 2024'!I48:I94)-SUM('BALANCE 2024'!H48:H94))) -> 0 | E8: =MAX(0,(SUM('BALANCE 2024'!I48:I94)-SUM('BALANCE 2024'!H48:H94))) -> 72698877 | F8: =MAX(0,(H8-I8)-(D8-E8)) -> 72698877 | G8: =MAX(0,(D8-E8)-(H8-I8)) -> 0 | H8: 0 | I8: 0 | J8: =(D8-E8)+(F8-G8)-(H8-I8) -> 0
A9: 162002 | B9: Emprunts auprès des établissements de crédit (BNI) | C9: DA | D9: ='BALANCE 2024'!H9 -> 0 | E9: ='BALANCE 2024'!I9 -> 39658832 | F9: =ROUND('INVEST ET FINANCEMENT'!D$47,0)+(H9-I9)-(D9-E9) -> 94054514 | G9: =ROUND('INVEST ET FINANCEMENT'!D$47,0) -> 54395682 | H9: 0 | I9: =ROUND(E9+'INVEST ET FINANCEMENT'!D$47-'INVEST ET FINANCEMENT'!D$48,0) -> 0 | J9: =(D9-E9)+(F9-G9)-(H9-I9) -> 0
A10: 173060 | B10: Dettes de location-acquisition | C10: DB | D10: ='BALANCE 2024'!H10 -> 0 | E10: ='BALANCE 2024'!I10 -> 10619694 | F10: =ROUND('INVEST ET FINANCEMENT'!D$49,0) -> 10619694 | G10: =ROUND('INVEST ET FINANCEMENT'!D$49,0)+(D10-E10)-(H10-I10) -> 0 | H10: 0 | I10: =ROUND(E10-'INVEST ET FINANCEMENT'!D$49,0) -> 0 | J10: =(D10-E10)+(F10-G10)-(H10-I10) -> 0
A11: 196100 | B11: Provisions pour pensions et obligations similaires (IFC) | C11: DC | D11: ='BALANCE 2024'!H11 -> 0 | E11: ='BALANCE 2024'!I11 -> 21273896 | F11: =ROUND(HYPOTHESES!D$20,0)+(H11-I11)-(D11-E11) -> 0 | G11: =ROUND(HYPOTHESES!D$20,0) -> 6059296 | H11: 0 | I11: =ROUND(E11+HYPOTHESES!D$20,0) -> 27333192 | J11: =(D11-E11)+(F11-G11)-(H11-I11) -> 0
A12: 234100 | B12: Aménagements, agencements et installations techniques | C12: AL | D12: ='BALANCE 2024'!H12 -> 103601492 | E12: ='BALANCE 2024'!I12 -> 0 | F12: =ROUND('INVEST ET FINANCEMENT'!D$9,0) -> 0 | G12: =ROUND('INVEST ET FINANCEMENT'!D$9,0)+(D12-E12)-(H12-I12) -> 0 | H12: =ROUND(D12+'INVEST ET FINANCEMENT'!D$9,0) -> 103601492 | I12: 0 | J12: =(D12-E12)+(F12-G12)-(H12-I12) -> 0
A13: 241100 | B13: Matériel industriel | C13: AM | D13: ='BALANCE 2024'!H13 -> 313845268 | E13: ='BALANCE 2024'!I13 -> 0 | F13: =ROUND('INVEST ET FINANCEMENT'!D$10,0) -> 0 | G13: =ROUND('INVEST ET FINANCEMENT'!D$10,0)+(D13-E13)-(H13-I13) -> 0 | H13: =ROUND(D13+'INVEST ET FINANCEMENT'!D$10,0) -> 313845268 | I13: 0 | J13: =(D13-E13)+(F13-G13)-(H13-I13) -> 0
A14: 244100 | B14: Matériel de bureau | C14: AM | D14: ='BALANCE 2024'!H14 -> 9306956 | E14: ='BALANCE 2024'!I14 -> 0 | F14: =MAX(0,(H14-I14)-(D14-E14)) -> 0 | G14: =MAX(0,(D14-E14)-(H14-I14)) -> 0 | H14: =ROUND(D14,0) -> 9306956 | I14: 0 | J14: =(D14-E14)+(F14-G14)-(H14-I14) -> 0
A15: 244200 | B15: Matériel informatique | C15: AM | D15: ='BALANCE 2024'!H15 -> 12980459 | E15: ='BALANCE 2024'!I15 -> 0 | F15: =ROUND('INVEST ET FINANCEMENT'!D$11,0) -> 930000 | G15: =ROUND('INVEST ET FINANCEMENT'!D$11,0)+(D15-E15)-(H15-I15) -> 0 | H15: =ROUND(D15+'INVEST ET FINANCEMENT'!D$11,0) -> 13910459 | I15: 0 | J15: =(D15-E15)+(F15-G15)-(H15-I15) -> 0
A16: 245100 | B16: Matériel automobile | C16: AN | D16: ='BALANCE 2024'!H16 -> 408044985 | E16: ='BALANCE 2024'!I16 -> 0 | F16: =ROUND('INVEST ET FINANCEMENT'!D$12,0) -> 15593220 | G16: =ROUND('INVEST ET FINANCEMENT'!D$12,0)+(D16-E16)-(H16-I16) -> 0 | H16: =ROUND(D16+'INVEST ET FINANCEMENT'!D$12,0) -> 423638205 | I16: 0 | J16: =(D16-E16)+(F16-G16)-(H16-I16) -> 0
A17: 245600 | B17: Matériel de transport en location-acquisition | C17: AN | D17: ='BALANCE 2024'!H17 -> 28619694 | E17: ='BALANCE 2024'!I17 -> 0 | F17: =MAX(0,(H17-I17)-(D17-E17)) -> 0 | G17: =MAX(0,(D17-E17)-(H17-I17)) -> 0 | H17: =ROUND(D17,0) -> 28619694 | I17: 0 | J17: =(D17-E17)+(F17-G17)-(H17-I17) -> 0
A18: 271800 | B18: Autres prêts et créances | C18: AS | D18: ='BALANCE 2024'!H18 -> 25000000 | E18: ='BALANCE 2024'!I18 -> 0 | F18: =MAX(0,(H18-I18)-(D18-E18)) -> 0 | G18: =MAX(0,(D18-E18)-(H18-I18)) -> 0 | H18: =ROUND(D18,0) -> 25000000 | I18: 0 | J18: =(D18-E18)+(F18-G18)-(H18-I18) -> 0
A19: 275100 | B19: Dépôts et cautionnements versés | C19: AS | D19: ='BALANCE 2024'!H19 -> 231420138 | E19: ='BALANCE 2024'!I19 -> 0 | F19: =ROUND('INVEST ET FINANCEMENT'!D$13,0) -> 0 | G19: =ROUND('INVEST ET FINANCEMENT'!D$13,0)+(D19-E19)-(H19-I19) -> 0 | H19: =ROUND(D19+'INVEST ET FINANCEMENT'!D$13,0) -> 231420138 | I19: 0 | J19: =(D19-E19)+(F19-G19)-(H19-I19) -> 0
A20: 283400 | B20: Amortissements des aménagements, agencements | C20: AL | D20: ='BALANCE 2024'!H20 -> 0 | E20: ='BALANCE 2024'!I20 -> 41936476 | F20: =ROUND('INVEST ET FINANCEMENT'!D$31,0)+(H20-I20)-(D20-E20) -> 0 | G20: =ROUND('INVEST ET FINANCEMENT'!D$31,0) -> 19282845 | H20: 0 | I20: =ROUND(E20+'INVEST ET FINANCEMENT'!D$31,0) -> 61219321 | J20: =(D20-E20)+(F20-G20)-(H20-I20) -> 0
A21: 284100 | B21: Amortissements du matériel et outillage | C21: AM | D21: ='BALANCE 2024'!H21 -> 0 | E21: ='BALANCE 2024'!I21 -> 55983764 | F21: =ROUND('INVEST ET FINANCEMENT'!D$34,0)+(H21-I21)-(D21-E21) -> 0 | G21: =ROUND('INVEST ET FINANCEMENT'!D$34,0) -> 28205053 | H21: 0 | I21: =ROUND(E21+'INVEST ET FINANCEMENT'!D$34,0) -> 84188817 | J21: =(D21-E21)+(F21-G21)-(H21-I21) -> 0
A22: 284400 | B22: Amortissements du matériel de bureau et informatique | C22: AM | D22: ='BALANCE 2024'!H22 -> 0 | E22: ='BALANCE 2024'!I22 -> 12708358 | F22: =ROUND('INVEST ET FINANCEMENT'!D$37,0)+(H22-I22)-(D22-E22) -> 0 | G22: =ROUND('INVEST ET FINANCEMENT'!D$37,0) -> 5399884 | H22: 0 | I22: =ROUND(E22+'INVEST ET FINANCEMENT'!D$37,0) -> 18108242 | J22: =(D22-E22)+(F22-G22)-(H22-I22) -> 0
A23: 284500 | B23: Amortissements du matériel de transport | C23: AN | D23: ='BALANCE 2024'!H23 -> 0 | E23: ='BALANCE 2024'!I23 -> 362909076 | F23: =ROUND('INVEST ET FINANCEMENT'!D$40,0)+(H23-I23)-(D23-E23) -> 0 | G23: =ROUND('INVEST ET FINANCEMENT'!D$40,0) -> 18958378 | H23: 0 | I23: =ROUND(E23+'INVEST ET FINANCEMENT'!D$40,0) -> 381867454 | J23: =(D23-E23)+(F23-G23)-(H23-I23) -> 0
A24: 401100 | B24: Fournisseurs | C24: DJ | D24: ='BALANCE 2024'!H24 -> 0 | E24: ='BALANCE 2024'!I24 -> 72947866 | F24: =ROUND(HYPOTHESES!D$49*(1+HYPOTHESES!D$10),0)+(H24-I24)-(D24-E24) -> 486035333 | G24: =ROUND(HYPOTHESES!D$49*(1+HYPOTHESES!D$10),0) -> 490796991 | H24: 0 | I24: =ROUND(HYPOTHESES!D$49*(1+HYPOTHESES!D$10)*HYPOTHESES!D$23/360,0) -> 77709524 | J24: =(D24-E24)+(F24-G24)-(H24-I24) -> 0
A25: 409100 | B25: Fournisseurs avances et accoptes ve | C25: BH | D25: ='BALANCE 2024'!H25 -> 0 | E25: ='BALANCE 2024'!I25 -> 0 | F25: =MAX(0,(H25-I25)-(D25-E25)) -> 0 | G25: =MAX(0,(D25-E25)-(H25-I25)) -> 0 | H25: =ROUND(D25,0) -> 0 | I25: =ROUND(E25,0) -> 0 | J25: =(D25-E25)+(F25-G25)-(H25-I25) -> 0
A26: 411100 | B26: Clients | C26: BI | D26: ='BALANCE 2024'!H26 -> 452271396 | E26: ='BALANCE 2024'!I26 -> 0 | F26: =ROUND(HYPOTHESES!D$42*(1+HYPOTHESES!D$10),0) -> 885116306 | G26: =ROUND(HYPOTHESES!D$42*(1+HYPOTHESES!D$10),0)+(D26-E26)-(H26-I26) -> 870242985 | H26: =ROUND(HYPOTHESES!D$42*(1+HYPOTHESES!D$10)*HYPOTHESES!D$22/360,0) -> 467144717 | I26: 0 | J26: =(D26-E26)+(F26-G26)-(H26-I26) -> 0
A27: 422000 | B27: Personnel, rémunérations dues | C27: DK | D27: ='BALANCE 2024'!H27 -> 0 | E27: ='BALANCE 2024'!I27 -> 11147549 | F27: =ROUND(IF(HYPOTHESES!$C$48=0,0,'BALANCE 2024'!$G$27*HYPOTHESES!D$48/HYPOTHESES!$C$48),0)+(H27-I27)-(D27-E27) -> 86159431 | G27: =ROUND(IF(HYPOTHESES!$C$48=0,0,'BALANCE 2024'!$G$27*HYPOTHESES!D$48/HYPOTHESES!$C$48),0) -> 86936353 | H27: 0 | I27: =ROUND(IF(HYPOTHESES!$C$48=0,0,'BALANCE 2024'!$I$27*HYPOTHESES!D$48/HYPOTHESES!$C$48),0) -> 11924471 | J27: =(D27-E27)+(F27-G27)-(H27-I27) -> 0
A28: 431301 | B28: CNPS, retraite part employeur | C28: DK | D28: ='BALANCE 2024'!H28 -> 0 | E28: ='BALANCE 2024'!I28 -> 4859377 | F28: =ROUND(IF(HYPOTHESES!$C$48=0,0,'BALANCE 2024'!$G$28*HYPOTHESES!D$48/HYPOTHESES!$C$48),0)+(H28-I28)-(D28-E28) -> 7154830 | G28: =ROUND(IF(HYPOTHESES!$C$48=0,0,'BALANCE 2024'!$G$28*HYPOTHESES!D$48/HYPOTHESES!$C$48),0) -> 7493502 | H28: 0 | I28: =ROUND(IF(HYPOTHESES!$C$48=0,0,'BALANCE 2024'!$I$28*HYPOTHESES!D$48/HYPOTHESES!$C$48),0) -> 5198049 | J28: =(D28-E28)+(F28-G28)-(H28-I28) -> 0
A29: 431302 | B29: CNPS, retraite part salariale | C29: DK | D29: ='BALANCE 2024'!H29 -> 0 | E29: ='BALANCE 2024'!I29 -> 1202405 | F29: =ROUND(IF(HYPOTHESES!$C$48=0,0,'BALANCE 2024'!$G$29*HYPOTHESES!D$48/HYPOTHESES!$C$48),0)+(H29-I29)-(D29-E29) -> 12174245 | G29: =ROUND(IF(HYPOTHESES!$C$48=0,0,'BALANCE 2024'!$G$29*HYPOTHESES!D$48/HYPOTHESES!$C$48),0) -> 12258046 | H29: 0 | I29: =ROUND(IF(HYPOTHESES!$C$48=0,0,'BALANCE 2024'!$I$29*HYPOTHESES!D$48/HYPOTHESES!$C$48),0) -> 1286206 | J29: =(D29-E29)+(F29-G29)-(H29-I29) -> 0
A30: 431802 | B30: CMU, part salariale | C30: DK | D30: ='BALANCE 2024'!H30 -> 0 | E30: ='BALANCE 2024'!I30 -> 161938 | F30: =ROUND(IF(HYPOTHESES!$C$48=0,0,'BALANCE 2024'!$G$30*HYPOTHESES!D$48/HYPOTHESES!$C$48),0)+(H30-I30)-(D30-E30) -> 403349 | G30: =ROUND(IF(HYPOTHESES!$C$48=0,0,'BALANCE 2024'!$G$30*HYPOTHESES!D$48/HYPOTHESES!$C$48),0) -> 414635 | H30: 0 | I30: =ROUND(IF(HYPOTHESES!$C$48=0,0,'BALANCE 2024'!$I$30*HYPOTHESES!D$48/HYPOTHESES!$C$48),0) -> 173224 | J30: =(D30-E30)+(F30-G30)-(H30-I30) -> 0
A31: 433300 | B31: Assurance et organisme de sante | C31: DK | D31: ='BALANCE 2024'!H31 -> 0 | E31: ='BALANCE 2024'!I31 -> 0 | F31: =ROUND(IF(HYPOTHESES!$C$48=0,0,'BALANCE 2024'!$G$31*HYPOTHESES!D$48/HYPOTHESES!$C$48),0)+(H31-I31)-(D31-E31) -> 0 | G31: =ROUND(IF(HYPOTHESES!$C$48=0,0,'BALANCE 2024'!$G$31*HYPOTHESES!D$48/HYPOTHESES!$C$48),0) -> 0 | H31: 0 | I31: =ROUND(IF(HYPOTHESES!$C$48=0,0,'BALANCE 2024'!$I$31*HYPOTHESES!D$48/HYPOTHESES!$C$48),0) -> 0 | J31: =(D31-E31)+(F31-G31)-(H31-I31) -> 0
A32: 441000 | B32: État, impôt sur les bénéfices | C32: DK | D32: ='BALANCE 2024'!H32 -> 0 | E32: ='BALANCE 2024'!I32 -> 24232959 | F32: =ROUND(HYPOTHESES!D$56,0)+(H32-I32)-(D32-E32) -> 24232959 | G32: =ROUND(HYPOTHESES!D$56,0) -> 30838289 | H32: 0 | I32: =ROUND(HYPOTHESES!D$56,0) -> 30838289 | J32: =(D32-E32)+(F32-G32)-(H32-I32) -> 0
A33: 442800 | B33: Autres impôts et taxes | C33: DK | D33: ='BALANCE 2024'!H33 -> 0 | E33: ='BALANCE 2024'!I33 -> 725658 | F33: =ROUND(IF(HYPOTHESES!$C$46=0,0,'BALANCE 2024'!$G$33*HYPOTHESES!D$46/HYPOTHESES!$C$46),0)+(H33-I33)-(D33-E33) -> 725658 | G33: =ROUND(IF(HYPOTHESES!$C$46=0,0,'BALANCE 2024'!$G$33*HYPOTHESES!D$46/HYPOTHESES!$C$46),0) -> 776041 | H33: 0 | I33: =ROUND(IF(HYPOTHESES!$C$46=0,0,'BALANCE 2024'!$I$33*HYPOTHESES!D$46/HYPOTHESES!$C$46),0) -> 776041 | J33: =(D33-E33)+(F33-G33)-(H33-I33) -> 0
A34: 442801 | B34: FDFP, taxe d'apprentissage | C34: DK | D34: ='BALANCE 2024'!H34 -> 0 | E34: ='BALANCE 2024'!I34 -> 104066 | F34: =ROUND(IF(HYPOTHESES!$C$46=0,0,'BALANCE 2024'!$G$34*HYPOTHESES!D$46/HYPOTHESES!$C$46),0)+(H34-I34)-(D34-E34) -> 104066 | G34: =ROUND(IF(HYPOTHESES!$C$46=0,0,'BALANCE 2024'!$G$34*HYPOTHESES!D$46/HYPOTHESES!$C$46),0) -> 111291 | H34: 0 | I34: =ROUND(IF(HYPOTHESES!$C$46=0,0,'BALANCE 2024'!$I$34*HYPOTHESES!D$46/HYPOTHESES!$C$46),0) -> 111291 | J34: =(D34-E34)+(F34-G34)-(H34-I34) -> 0
A35: 442802 | B35: FDFP, formation continue | C35: DK | D35: ='BALANCE 2024'!H35 -> 0 | E35: ='BALANCE 2024'!I35 -> 156106 | F35: =ROUND(IF(HYPOTHESES!$C$46=0,0,'BALANCE 2024'!$G$35*HYPOTHESES!D$46/HYPOTHESES!$C$46),0)+(H35-I35)-(D35-E35) -> 156106 | G35: =ROUND(IF(HYPOTHESES!$C$46=0,0,'BALANCE 2024'!$G$35*HYPOTHESES!D$46/HYPOTHESES!$C$46),0) -> 166945 | H35: 0 | I35: =ROUND(IF(HYPOTHESES!$C$46=0,0,'BALANCE 2024'!$I$35*HYPOTHESES!D$46/HYPOTHESES!$C$46),0) -> 166945 | J35: =(D35-E35)+(F35-G35)-(H35-I35) -> 0
A36: 442803 | B36: FDFP, FPC à régulariser | C36: DK | D36: ='BALANCE 2024'!H36 -> 0 | E36: ='BALANCE 2024'!I36 -> 156105 | F36: =ROUND(IF(HYPOTHESES!$C$46=0,0,'BALANCE 2024'!$G$36*HYPOTHESES!D$46/HYPOTHESES!$C$46),0)+(H36-I36)-(D36-E36) -> 156105 | G36: =ROUND(IF(HYPOTHESES!$C$46=0,0,'BALANCE 2024'!$G$36*HYPOTHESES!D$46/HYPOTHESES!$C$46),0) -> 166944 | H36: 0 | I36: =ROUND(IF(HYPOTHESES!$C$46=0,0,'BALANCE 2024'!$I$36*HYPOTHESES!D$46/HYPOTHESES!$C$46),0) -> 166944 | J36: =(D36-E36)+(F36-G36)-(H36-I36) -> 0
A37: 442820 | B37: Impôt sur salaires, part patronale | C37: DK | D37: ='BALANCE 2024'!H37 -> 0 | E37: ='BALANCE 2024'!I37 -> 367610 | F37: =ROUND(IF(HYPOTHESES!$C$46=0,0,'BALANCE 2024'!$G$37*HYPOTHESES!D$46/HYPOTHESES!$C$46),0)+(H37-I37)-(D37-E37) -> 858441 | G37: =ROUND(IF(HYPOTHESES!$C$46=0,0,'BALANCE 2024'!$G$37*HYPOTHESES!D$46/HYPOTHESES!$C$46),0) -> 883965 | H37: 0 | I37: =ROUND(IF(HYPOTHESES!$C$46=0,0,'BALANCE 2024'!$I$37*HYPOTHESES!D$46/HYPOTHESES!$C$46),0) -> 393134 | J37: =(D37-E37)+(F37-G37)-(H37-I37) -> 0
A38: 442840 | B38: Patente | C38: DK | D38: ='BALANCE 2024'!H38 -> 0 | E38: ='BALANCE 2024'!I38 -> 5000000 | F38: =ROUND(IF(HYPOTHESES!$C$46=0,0,'BALANCE 2024'!$G$38*HYPOTHESES!D$46/HYPOTHESES!$C$46),0)+(H38-I38)-(D38-E38) -> 9336686 | G38: =ROUND(IF(HYPOTHESES!$C$46=0,0,'BALANCE 2024'!$G$38*HYPOTHESES!D$46/HYPOTHESES!$C$46),0) -> 9683842 | H38: 0 | I38: =ROUND(IF(HYPOTHESES!$C$46=0,0,'BALANCE 2024'!$I$38*HYPOTHESES!D$46/HYPOTHESES!$C$46),0) -> 5347156 | J38: =(D38-E38)+(F38-G38)-(H38-I38) -> 0
A39: 443300 | B39: État, TVA facturée sur travaux (en attente) | C39: DK | D39: ='BALANCE 2024'!H39 -> 0 | E39: ='BALANCE 2024'!I39 -> 52145698 | F39: =ROUND(HYPOTHESES!D$42*HYPOTHESES!D$10,0)+(H39-I39)-(D39-E39) -> 133302887 | G39: =ROUND(HYPOTHESES!D$42*HYPOTHESES!D$10,0) -> 135017742 | H39: 0 | I39: =ROUND(IF('BALANCE 2024'!$H$26=0,0,'BALANCE 2024'!$I$39*H26/'BALANCE 2024'!$H$26),0) -> 53860553 | J39: =(D39-E39)+(F39-G39)-(H39-I39) -> 0
A40: 446000 | B40: Taxe spéciale d'équipement | C40: DK | D40: ='BALANCE 2024'!H40 -> 0 | E40: ='BALANCE 2024'!I40 -> 200000 | F40: =ROUND(IF(HYPOTHESES!$C$46=0,0,'BALANCE 2024'!$G$40*HYPOTHESES!D$46/HYPOTHESES!$C$46),0)+(H40-I40)-(D40-E40) -> 212497 | G40: =ROUND(IF(HYPOTHESES!$C$46=0,0,'BALANCE 2024'!$G$40*HYPOTHESES!D$46/HYPOTHESES!$C$46),0) -> 226383 | H40: 0 | I40: =ROUND(IF(HYPOTHESES!$C$46=0,0,'BALANCE 2024'!$I$40*HYPOTHESES!D$46/HYPOTHESES!$C$46),0) -> 213886 | J40: =(D40-E40)+(F40-G40)-(H40-I40) -> 0
...

Sheet BALANCE 2026
A1: BALANCE GÉNÉRALE À 6 COLONNES : EXERCICE 2026 (PRÉVISIONNEL)
A2: Ouverture = clôture de l'exercice précédent (classes 6 à 8 soldées, résultat N-1 en 13). Clôture calculée depuis les hypothèses ; mouvements = flux de l'exercice. Soldes après inventaire, avant écritures de clôture. Ne rien saisir.
D3: Soldes d'ouverture | F3: Mouvements de l'exercice | H3: Soldes de clôture | J3: Contrôle
A4: Compte | B4: Intitulé | C4: Poste | D4: Débit | E4: Crédit | F4: Débit | G4: Crédit | H4: Débit | I4: Crédit | J4: Ouv.+Mvts-Clôt.
A5: 101000 | B5: Capital social | C5: CA | D5: ='BALANCE 2025'!H5 -> 0 | E5: ='BALANCE 2025'!I5 -> 10000000 | F5: =ROUND('INVEST ET FINANCEMENT'!E$51,0)+(H5-I5)-(D5-E5) -> 0 | G5: =ROUND('INVEST ET FINANCEMENT'!E$51,0) -> 0 | H5: 0 | I5: =ROUND(E5+'INVEST ET FINANCEMENT'!E$51,0) -> 10000000 | J5: =(D5-E5)+(F5-G5)-(H5-I5) -> 0
A6: 111000 | B6: Réserve légale | C6: CF | D6: ='BALANCE 2025'!H6 -> 0 | E6: ='BALANCE 2025'!I6 -> 2000000 | F6: =ROUND(HYPOTHESES!E$58,0)+(H6-I6)-(D6-E6) -> 0 | G6: =ROUND(HYPOTHESES!E$58,0) -> 0 | H6: 0 | I6: =ROUND(E6+HYPOTHESES!E$58,0) -> 2000000 | J6: =(D6-E6)+(F6-G6)-(H6-I6) -> 0
A7: 121000 | B7: Report à nouveau | C7: CH | D7: ='BALANCE 2025'!H7 -> 0 | E7: ='BALANCE 2025'!I7 -> 844498728 | F7: =MAX(0,(H7-I7)-(D7-E7)) -> 0 | G7: =MAX(0,(D7-E7)-(H7-I7)) -> 92514868 | H7: =ROUND(MAX(0,-(E7-D7+HYPOTHESES!E$60)),0) -> 0 | I7: =ROUND(MAX(0,(E7-D7+HYPOTHESES!E$60)),0) -> 937013596 | J7: =(D7-E7)+(F7-G7)-(H7-I7) -> 0
A8: 130100 | B8: Résultat en instance d'affectation : bénéfice | C8: R13 | D8: =MAX(0,-(SUM('BALANCE 2025'!I48:I94)-SUM('BALANCE 2025'!H48:H94))) -> 0 | E8: =MAX(0,(SUM('BALANCE 2025'!I48:I94)-SUM('BALANCE 2025'!H48:H94))) -> 92514868 | F8: =MAX(0,(H8-I8)-(D8-E8)) -> 92514868 | G8: =MAX(0,(D8-E8)-(H8-I8)) -> 0 | H8: 0 | I8: 0 | J8: =(D8-E8)+(F8-G8)-(H8-I8) -> 0
A9: 162002 | B9: Emprunts auprès des établissements de crédit (BNI) | C9: DA | D9: ='BALANCE 2025'!H9 -> 0 | E9: ='BALANCE 2025'!I9 -> 0 | F9: =ROUND('INVEST ET FINANCEMENT'!E$47,0)+(H9-I9)-(D9-E9) -> 0 | G9: =ROUND('INVEST ET FINANCEMENT'!E$47,0) -> 0 | H9: 0 | I9: =ROUND(E9+'INVEST ET FINANCEMENT'!E$47-'INVEST ET FINANCEMENT'!E$48,0) -> 0 | J9: =(D9-E9)+(F9-G9)-(H9-I9) -> 0
A10: 173060 | B10: Dettes de location-acquisition | C10: DB | D10: ='BALANCE 2025'!H10 -> 0 | E10: ='BALANCE 2025'!I10 -> 0 | F10: =ROUND('INVEST ET FINANCEMENT'!E$49,0) -> 0 | G10: =ROUND('INVEST ET FINANCEMENT'!E$49,0)+(D10-E10)-(H10-I10) -> 0 | H10: 0 | I10: =ROUND(E10-'INVEST ET FINANCEMENT'!E$49,0) -> 0 | J10: =(D10-E10)+(F10-G10)-(H10-I10) -> 0
A11: 196100 | B11: Provisions pour pensions et obligations similaires (IFC) | C11: DC | D11: ='BALANCE 2025'!H11 -> 0 | E11: ='BALANCE 2025'!I11 -> 27333192 | F11: =ROUND(HYPOTHESES!E$20,0)+(H11-I11)-(D11-E11) -> 0 | G11: =ROUND(HYPOTHESES!E$20,0) -> 6059296 | H11: 0 | I11: =ROUND(E11+HYPOTHESES!E$20,0) -> 33392488 | J11: =(D11-E11)+(F11-G11)-(H11-I11) -> 0
A12: 234100 | B12: Aménagements, agencements et installations techniques | C12: AL | D12: ='BALANCE 2025'!H12 -> 103601492 | E12: ='BALANCE 2025'!I12 -> 0 | F12: =ROUND('INVEST ET FINANCEMENT'!E$9,0) -> 0 | G12: =ROUND('INVEST ET FINANCEMENT'!E$9,0)+(D12-E12)-(H12-I12) -> 0 | H12: =ROUND(D12+'INVEST ET FINANCEMENT'!E$9,0) -> 103601492 | I12: 0 | J12: =(D12-E12)+(F12-G12)-(H12-I12) -> 0
A13: 241100 | B13: Matériel industriel | C13: AM | D13: ='BALANCE 2025'!H13 -> 313845268 | E13: ='BALANCE 2025'!I13 -> 0 | F13: =ROUND('INVEST ET FINANCEMENT'!E$10,0) -> 30000000 | G13: =ROUND('INVEST ET FINANCEMENT'!E$10,0)+(D13-E13)-(H13-I13) -> 0 | H13: =ROUND(D13+'INVEST ET FINANCEMENT'!E$10,0) -> 343845268 | I13: 0 | J13: =(D13-E13)+(F13-G13)-(H13-I13) -> 0
A14: 244100 | B14: Matériel de bureau | C14: AM | D14: ='BALANCE 2025'!H14 -> 9306956 | E14: ='BALANCE 2025'!I14 -> 0 | F14: =MAX(0,(H14-I14)-(D14-E14)) -> 0 | G14: =MAX(0,(D14-E14)-(H14-I14)) -> 0 | H14: =ROUND(D14,0) -> 9306956 | I14: 0 | J14: =(D14-E14)+(F14-G14)-(H14-I14) -> 0
A15: 244200 | B15: Matériel informatique | C15: AM | D15: ='BALANCE 2025'!H15 -> 13910459 | E15: ='BALANCE 2025'!I15 -> 0 | F15: =ROUND('INVEST ET FINANCEMENT'!E$11,0) -> 5000000 | G15: =ROUND('INVEST ET FINANCEMENT'!E$11,0)+(D15-E15)-(H15-I15) -> 0 | H15: =ROUND(D15+'INVEST ET FINANCEMENT'!E$11,0) -> 18910459 | I15: 0 | J15: =(D15-E15)+(F15-G15)-(H15-I15) -> 0
A16: 245100 | B16: Matériel automobile | C16: AN | D16: ='BALANCE 2025'!H16 -> 423638205 | E16: ='BALANCE 2025'!I16 -> 0 | F16: =ROUND('INVEST ET FINANCEMENT'!E$12,0) -> 0 | G16: =ROUND('INVEST ET FINANCEMENT'!E$12,0)+(D16-E16)-(H16-I16) -> 0 | H16: =ROUND(D16+'INVEST ET FINANCEMENT'!E$12,0) -> 423638205 | I16: 0 | J16: =(D16-E16)+(F16-G16)-(H16-I16) -> 0
A17: 245600 | B17: Matériel de transport en location-acquisition | C17: AN | D17: ='BALANCE 2025'!H17 -> 28619694 | E17: ='BALANCE 2025'!I17 -> 0 | F17: =MAX(0,(H17-I17)-(D17-E17)) -> 0 | G17: =MAX(0,(D17-E17)-(H17-I17)) -> 0 | H17: =ROUND(D17,0) -> 28619694 | I17: 0 | J17: =(D17-E17)+(F17-G17)-(H17-I17) -> 0
A18: 271800 | B18: Autres prêts et créances | C18: AS | D18: ='BALANCE 2025'!H18 -> 25000000 | E18: ='BALANCE 2025'!I18 -> 0 | F18: =MAX(0,(H18-I18)-(D18-E18)) -> 0 | G18: =MAX(0,(D18-E18)-(H18-I18)) -> 0 | H18: =ROUND(D18,0) -> 25000000 | I18: 0 | J18: =(D18-E18)+(F18-G18)-(H18-I18) -> 0
A19: 275100 | B19: Dépôts et cautionnements versés | C19: AS | D19: ='BALANCE 2025'!H19 -> 231420138 | E19: ='BALANCE 2025'!I19 -> 0 | F19: =ROUND('INVEST ET FINANCEMENT'!E$13,0) -> 0 | G19: =ROUND('INVEST ET FINANCEMENT'!E$13,0)+(D19-E19)-(H19-I19) -> 0 | H19: =ROUND(D19+'INVEST ET FINANCEMENT'!E$13,0) -> 231420138 | I19: 0 | J19: =(D19-E19)+(F19-G19)-(H19-I19) -> 0
A20: 283400 | B20: Amortissements des aménagements, agencements | C20: AL | D20: ='BALANCE 2025'!H20 -> 0 | E20: ='BALANCE 2025'!I20 -> 61219321 | F20: =ROUND('INVEST ET FINANCEMENT'!E$31,0)+(H20-I20)-(D20-E20) -> 0 | G20: =ROUND('INVEST ET FINANCEMENT'!E$31,0) -> 19282845 | H20: 0 | I20: =ROUND(E20+'INVEST ET FINANCEMENT'!E$31,0) -> 80502166 | J20: =(D20-E20)+(F20-G20)-(H20-I20) -> 0
A21: 284100 | B21: Amortissements du matériel et outillage | C21: AM | D21: ='BALANCE 2025'!H21 -> 0 | E21: ='BALANCE 2025'!I21 -> 84188817 | F21: =ROUND('INVEST ET FINANCEMENT'!E$34,0)+(H21-I21)-(D21-E21) -> 0 | G21: =ROUND('INVEST ET FINANCEMENT'!E$34,0) -> 50854932 | H21: 0 | I21: =ROUND(E21+'INVEST ET FINANCEMENT'!E$34,0) -> 135043749 | J21: =(D21-E21)+(F21-G21)-(H21-I21) -> 0
A22: 284400 | B22: Amortissements du matériel de bureau et informatique | C22: AM | D22: ='BALANCE 2025'!H22 -> 0 | E22: ='BALANCE 2025'!I22 -> 18108242 | F22: =ROUND('INVEST ET FINANCEMENT'!E$37,0)+(H22-I22)-(D22-E22) -> 0 | G22: =ROUND('INVEST ET FINANCEMENT'!E$37,0) -> 7609173 | H22: 0 | I22: =ROUND(E22+'INVEST ET FINANCEMENT'!E$37,0) -> 25717415 | J22: =(D22-E22)+(F22-G22)-(H22-I22) -> 0
A23: 284500 | B23: Amortissements du matériel de transport | C23: AN | D23: ='BALANCE 2025'!H23 -> 0 | E23: ='BALANCE 2025'!I23 -> 381867454 | F23: =ROUND('INVEST ET FINANCEMENT'!E$40,0)+(H23-I23)-(D23-E23) -> 0 | G23: =ROUND('INVEST ET FINANCEMENT'!E$40,0) -> 15958378 | H23: 0 | I23: =ROUND(E23+'INVEST ET FINANCEMENT'!E$40,0) -> 397825832 | J23: =(D23-E23)+(F23-G23)-(H23-I23) -> 0
A24: 401100 | B24: Fournisseurs | C24: DJ | D24: ='BALANCE 2025'!H24 -> 0 | E24: ='BALANCE 2025'!I24 -> 77709524 | F24: =ROUND(HYPOTHESES!E$49*(1+HYPOTHESES!E$10),0)+(H24-I24)-(D24-E24) -> 511451366 | G24: =ROUND(HYPOTHESES!E$49*(1+HYPOTHESES!E$10),0) -> 515336842 | H24: 0 | I24: =ROUND(HYPOTHESES!E$49*(1+HYPOTHESES!E$10)*HYPOTHESES!E$23/360,0) -> 81595000 | J24: =(D24-E24)+(F24-G24)-(H24-I24) -> 0
A25: 409100 | B25: Fournisseurs avances et accoptes ve | C25: BH | D25: ='BALANCE 2025'!H25 -> 0 | E25: ='BALANCE 2025'!I25 -> 0 | F25: =MAX(0,(H25-I25)-(D25-E25)) -> 0 | G25: =MAX(0,(D25-E25)-(H25-I25)) -> 0 | H25: =ROUND(D25,0) -> 0 | I25: =ROUND(E25,0) -> 0 | J25: =(D25-E25)+(F25-G25)-(H25-I25) -> 0
A26: 411100 | B26: Clients | C26: BI | D26: ='BALANCE 2025'!H26 -> 467144717 | E26: ='BALANCE 2025'!I26 -> 0 | F26: =ROUND(HYPOTHESES!E$42*(1+HYPOTHESES!E$10),0) -> 929372121 | G26: =ROUND(HYPOTHESES!E$42*(1+HYPOTHESES!E$10),0)+(D26-E26)-(H26-I26) -> 887943761 | H26: =ROUND(HYPOTHESES!E$42*(1+HYPOTHESES!E$10)*HYPOTHESES!E$22/360,0) -> 508573077 | I26: 0 | J26: =(D26-E26)+(F26-G26)-(H26-I26) -> 0
A27: 422000 | B27: Personnel, rémunérations dues | C27: DK | D27: ='BALANCE 2025'!H27 -> 0 | E27: ='BALANCE 2025'!I27 -> 11924471 | F27: =ROUND(IF(HYPOTHESES!$C$48=0,0,'BALANCE 2024'!$G$27*HYPOTHESES!E$48/HYPOTHESES!$C$48),0)+(H27-I27)-(D27-E27) -> 90686947 | G27: =ROUND(IF(HYPOTHESES!$C$48=0,0,'BALANCE 2024'!$G$27*HYPOTHESES!E$48/HYPOTHESES!$C$48),0) -> 91283171 | H27: 0 | I27: =ROUND(IF(HYPOTHESES!$C$48=0,0,'BALANCE 2024'!$I$27*HYPOTHESES!E$48/HYPOTHESES!$C$48),0) -> 12520695 | J27: =(D27-E27)+(F27-G27)-(H27-I27) -> 0
A28: 431301 | B28: CNPS, retraite part employeur | C28: DK | D28: ='BALANCE 2025'!H28 -> 0 | E28: ='BALANCE 2025'!I28 -> 5198049 | F28: =ROUND(IF(HYPOTHESES!$C$48=0,0,'BALANCE 2024'!$G$28*HYPOTHESES!E$48/HYPOTHESES!$C$48),0)+(H28-I28)-(D28-E28) -> 7608275 | G28: =ROUND(IF(HYPOTHESES!$C$48=0,0,'BALANCE 2024'!$G$28*HYPOTHESES!E$48/HYPOTHESES!$C$48),0) -> 7868177 | H28: 0 | I28: =ROUND(IF(HYPOTHESES!$C$48=0,0,'BALANCE 2024'!$I$28*HYPOTHESES!E$48/HYPOTHESES!$C$48),0) -> 5457951 | J28: =(D28-E28)+(F28-G28)-(H28-I28) -> 0
A29: 431302 | B29: CNPS, retraite part salariale | C29: DK | D29: ='BALANCE 2025'!H29 -> 0 | E29: ='BALANCE 2025'!I29 -> 1286206 | F29: =ROUND(IF(HYPOTHESES!$C$48=0,0,'BALANCE 2024'!$G$29*HYPOTHESES!E$48/HYPOTHESES!$C$48),0)+(H29-I29)-(D29-E29) -> 12806638 | G29: =ROUND(IF(HYPOTHESES!$C$48=0,0,'BALANCE 2024'!$G$29*HYPOTHESES!E$48/HYPOTHESES!$C$48),0) -> 12870948 | H29: 0 | I29: =ROUND(IF(HYPOTHESES!$C$48=0,0,'BALANCE 2024'!$I$29*HYPOTHESES!E$48/HYPOTHESES!$C$48),0) -> 1350516 | J29: =(D29-E29)+(F29-G29)-(H29-I29) -> 0
A30: 431802 | B30: CMU, part salariale | C30: DK | D30: ='BALANCE 2025'!H30 -> 0 | E30: ='BALANCE 2025'!I30 -> 173224 | F30: =ROUND(IF(HYPOTHESES!$C$48=0,0,'BALANCE 2024'!$G$30*HYPOTHESES!E$48/HYPOTHESES!$C$48),0)+(H30-I30)-(D30-E30) -> 426706 | G30: =ROUND(IF(HYPOTHESES!$C$48=0,0,'BALANCE 2024'!$G$30*HYPOTHESES!E$48/HYPOTHESES!$C$48),0) -> 435367 | H30: 0 | I30: =ROUND(IF(HYPOTHESES!$C$48=0,0,'BALANCE 2024'!$I$30*HYPOTHESES!E$48/HYPOTHESES!$C$48),0) -> 181885 | J30: =(D30-E30)+(F30-G30)-(H30-I30) -> 0
A31: 433300 | B31: Assurance et organisme de sante | C31: DK | D31: ='BALANCE 2025'!H31 -> 0 | E31: ='BALANCE 2025'!I31 -> 0 | F31: =ROUND(IF(HYPOTHESES!$C$48=0,0,'BALANCE 2024'!$G$31*HYPOTHESES!E$48/HYPOTHESES!$C$48),0)+(H31-I31)-(D31-E31) -> 0 | G31: =ROUND(IF(HYPOTHESES!$C$48=0,0,'BALANCE 2024'!$G$31*HYPOTHESES!E$48/HYPOTHESES!$C$48),0) -> 0 | H31: 0 | I31: =ROUND(IF(HYPOTHESES!$C$48=0,0,'BALANCE 2024'!$I$31*HYPOTHESES!E$48/HYPOTHESES!$C$48),0) -> 0 | J31: =(D31-E31)+(F31-G31)-(H31-I31) -> 0
A32: 441000 | B32: État, impôt sur les bénéfices | C32: DK | D32: ='BALANCE 2025'!H32 -> 0 | E32: ='BALANCE 2025'!I32 -> 30838289 | F32: =ROUND(HYPOTHESES!E$56,0)+(H32-I32)-(D32-E32) -> 30838289 | G32: =ROUND(HYPOTHESES!E$56,0) -> 28670509 | H32: 0 | I32: =ROUND(HYPOTHESES!E$56,0) -> 28670509 | J32: =(D32-E32)+(F32-G32)-(H32-I32) -> 0
A33: 442800 | B33: Autres impôts et taxes | C33: DK | D33: ='BALANCE 2025'!H33 -> 0 | E33: ='BALANCE 2025'!I33 -> 776041 | F33: =ROUND(IF(HYPOTHESES!$C$46=0,0,'BALANCE 2024'!$G$33*HYPOTHESES!E$46/HYPOTHESES!$C$46),0)+(H33-I33)-(D33-E33) -> 776041 | G33: =ROUND(IF(HYPOTHESES!$C$46=0,0,'BALANCE 2024'!$G$33*HYPOTHESES!E$46/HYPOTHESES!$C$46),0) -> 814843 | H33: 0 | I33: =ROUND(IF(HYPOTHESES!$C$46=0,0,'BALANCE 2024'!$I$33*HYPOTHESES!E$46/HYPOTHESES!$C$46),0) -> 814843 | J33: =(D33-E33)+(F33-G33)-(H33-I33) -> 0
A34: 442801 | B34: FDFP, taxe d'apprentissage | C34: DK | D34: ='BALANCE 2025'!H34 -> 0 | E34: ='BALANCE 2025'!I34 -> 111291 | F34: =ROUND(IF(HYPOTHESES!$C$46=0,0,'BALANCE 2024'!$G$34*HYPOTHESES!E$46/HYPOTHESES!$C$46),0)+(H34-I34)-(D34-E34) -> 111291 | G34: =ROUND(IF(HYPOTHESES!$C$46=0,0,'BALANCE 2024'!$G$34*HYPOTHESES!E$46/HYPOTHESES!$C$46),0) -> 116856 | H34: 0 | I34: =ROUND(IF(HYPOTHESES!$C$46=0,0,'BALANCE 2024'!$I$34*HYPOTHESES!E$46/HYPOTHESES!$C$46),0) -> 116856 | J34: =(D34-E34)+(F34-G34)-(H34-I34) -> 0
A35: 442802 | B35: FDFP, formation continue | C35: DK | D35: ='BALANCE 2025'!H35 -> 0 | E35: ='BALANCE 2025'!I35 -> 166945 | F35: =ROUND(IF(HYPOTHESES!$C$46=0,0,'BALANCE 2024'!$G$35*HYPOTHESES!E$46/HYPOTHESES!$C$46),0)+(H35-I35)-(D35-E35) -> 166945 | G35: =ROUND(IF(HYPOTHESES!$C$46=0,0,'BALANCE 2024'!$G$35*HYPOTHESES!E$46/HYPOTHESES!$C$46),0) -> 175292 | H35: 0 | I35: =ROUND(IF(HYPOTHESES!$C$46=0,0,'BALANCE 2024'!$I$35*HYPOTHESES!E$46/HYPOTHESES!$C$46),0) -> 175292 | J35: =(D35-E35)+(F35-G35)-(H35-I35) -> 0
A36: 442803 | B36: FDFP, FPC à régulariser | C36: DK | D36: ='BALANCE 2025'!H36 -> 0 | E36: ='BALANCE 2025'!I36 -> 166944 | F36: =ROUND(IF(HYPOTHESES!$C$46=0,0,'BALANCE 2024'!$G$36*HYPOTHESES!E$46/HYPOTHESES!$C$46),0)+(H36-I36)-(D36-E36) -> 166944 | G36: =ROUND(IF(HYPOTHESES!$C$46=0,0,'BALANCE 2024'!$G$36*HYPOTHESES!E$46/HYPOTHESES!$C$46),0) -> 175291 | H36: 0 | I36: =ROUND(IF(HYPOTHESES!$C$46=0,0,'BALANCE 2024'!$I$36*HYPOTHESES!E$46/HYPOTHESES!$C$46),0) -> 175291 | J36: =(D36-E36)+(F36-G36)-(H36-I36) -> 0
A37: 442820 | B37: Impôt sur salaires, part patronale | C37: DK | D37: ='BALANCE 2025'!H37 -> 0 | E37: ='BALANCE 2025'!I37 -> 393134 | F37: =ROUND(IF(HYPOTHESES!$C$46=0,0,'BALANCE 2024'!$G$37*HYPOTHESES!E$46/HYPOTHESES!$C$46),0)+(H37-I37)-(D37-E37) -> 908507 | G37: =ROUND(IF(HYPOTHESES!$C$46=0,0,'BALANCE 2024'!$G$37*HYPOTHESES!E$46/HYPOTHESES!$C$46),0) -> 928163 | H37: 0 | I37: =ROUND(IF(HYPOTHESES!$C$46=0,0,'BALANCE 2024'!$I$37*HYPOTHESES!E$46/HYPOTHESES!$C$46),0) -> 412790 | J37: =(D37-E37)+(F37-G37)-(H37-I37) -> 0
A38: 442840 | B38: Patente | C38: DK | D38: ='BALANCE 2025'!H38 -> 0 | E38: ='BALANCE 2025'!I38 -> 5347156 | F38: =ROUND(IF(HYPOTHESES!$C$46=0,0,'BALANCE 2024'!$G$38*HYPOTHESES!E$46/HYPOTHESES!$C$46),0)+(H38-I38)-(D38-E38) -> 9900676 | G38: =ROUND(IF(HYPOTHESES!$C$46=0,0,'BALANCE 2024'!$G$38*HYPOTHESES!E$46/HYPOTHESES!$C$46),0) -> 10168034 | H38: 0 | I38: =ROUND(IF(HYPOTHESES!$C$46=0,0,'BALANCE 2024'!$I$38*HYPOTHESES!E$46/HYPOTHESES!$C$46),0) -> 5614514 | J38: =(D38-E38)+(F38-G38)-(H38-I38) -> 0
A39: 443300 | B39: État, TVA facturée sur travaux (en attente) | C39: DK | D39: ='BALANCE 2025'!H39 -> 0 | E39: ='BALANCE 2025'!I39 -> 53860553 | F39: =ROUND(HYPOTHESES!E$42*HYPOTHESES!E$10,0)+(H39-I39)-(D39-E39) -> 136992049 | G39: =ROUND(HYPOTHESES!E$42*HYPOTHESES!E$10,0) -> 141768629 | H39: 0 | I39: =ROUND(IF('BALANCE 2024'!$H$26=0,0,'BALANCE 2024'!$I$39*H26/'BALANCE 2024'!$H$26),0) -> 58637133 | J39: =(D39-E39)+(F39-G39)-(H39-I39) -> 0
A40: 446000 | B40: Taxe spéciale d'équipement | C40: DK | D40: ='BALANCE 2025'!H40 -> 0 | E40: ='BALANCE 2025'!I40 -> 213886 | F40: =ROUND(IF(HYPOTHESES!$C$46=0,0,'BALANCE 2024'!$G$40*HYPOTHESES!E$46/HYPOTHESES!$C$46),0)+(H40-I40)-(D40-E40) -> 227007 | G40: =ROUND(IF(HYPOTHESES!$C$46=0,0,'BALANCE 2024'!$G$40*HYPOTHESES!E$46/HYPOTHESES!$C$46),0) -> 237702 | H40: 0 | I40: =ROUND(IF(HYPOTHESES!$C$46=0,0,'BALANCE 2024'!$I$40*HYPOTHESES!E$46/HYPOTHESES!$C$46),0) -> 224581 | J40: =(D40-E40)+(F40-G40)-(H40-I40) -> 0
...

Sheet BALANCE 2027
A1: BALANCE GÉNÉRALE À 6 COLONNES : EXERCICE 2027 (PRÉVISIONNEL)
A2: Ouverture = clôture de l'exercice précédent (classes 6 à 8 soldées, résultat N-1 en 13). Clôture calculée depuis les hypothèses ; mouvements = flux de l'exercice. Soldes après inventaire, avant écritures de clôture. Ne rien saisir.
D3: Soldes d'ouverture | F3: Mouvements de l'exercice | H3: Soldes de clôture | J3: Contrôle
A4: Compte | B4: Intitulé | C4: Poste | D4: Débit | E4: Crédit | F4: Débit | G4: Crédit | H4: Débit | I4: Crédit | J4: Ouv.+Mvts-Clôt.
A5: 101000 | B5: Capital social | C5: CA | D5: ='BALANCE 2026'!H5 -> 0 | E5: ='BALANCE 2026'!I5 -> 10000000 | F5: =ROUND('INVEST ET FINANCEMENT'!F$51,0)+(H5-I5)-(D5-E5) -> 0 | G5: =ROUND('INVEST ET FINANCEMENT'!F$51,0) -> 0 | H5: 0 | I5: =ROUND(E5+'INVEST ET FINANCEMENT'!F$51,0) -> 10000000 | J5: =(D5-E5)+(F5-G5)-(H5-I5) -> 0
A6: 111000 | B6: Réserve légale | C6: CF | D6: ='BALANCE 2026'!H6 -> 0 | E6: ='BALANCE 2026'!I6 -> 2000000 | F6: =ROUND(HYPOTHESES!F$58,0)+(H6-I6)-(D6-E6) -> 0 | G6: =ROUND(HYPOTHESES!F$58,0) -> 0 | H6: 0 | I6: =ROUND(E6+HYPOTHESES!F$58,0) -> 2000000 | J6: =(D6-E6)+(F6-G6)-(H6-I6) -> 0
A7: 121000 | B7: Report à nouveau | C7: CH | D7: ='BALANCE 2026'!H7 -> 0 | E7: ='BALANCE 2026'!I7 -> 937013596 | F7: =MAX(0,(H7-I7)-(D7-E7)) -> 0 | G7: =MAX(0,(D7-E7)-(H7-I7)) -> 86011527 | H7: =ROUND(MAX(0,-(E7-D7+HYPOTHESES!F$60)),0) -> 0 | I7: =ROUND(MAX(0,(E7-D7+HYPOTHESES!F$60)),0) -> 1023025123 | J7: =(D7-E7)+(F7-G7)-(H7-I7) -> 0
A8: 130100 | B8: Résultat en instance d'affectation : bénéfice | C8: R13 | D8: =MAX(0,-(SUM('BALANCE 2026'!I48:I94)-SUM('BALANCE 2026'!H48:H94))) -> 0 | E8: =MAX(0,(SUM('BALANCE 2026'!I48:I94)-SUM('BALANCE 2026'!H48:H94))) -> 86011527 | F8: =MAX(0,(H8-I8)-(D8-E8)) -> 86011527 | G8: =MAX(0,(D8-E8)-(H8-I8)) -> 0 | H8: 0 | I8: 0 | J8: =(D8-E8)+(F8-G8)-(H8-I8) -> 0
A9: 162002 | B9: Emprunts auprès des établissements de crédit (BNI) | C9: DA | D9: ='BALANCE 2026'!H9 -> 0 | E9: ='BALANCE 2026'!I9 -> 0 | F9: =ROUND('INVEST ET FINANCEMENT'!F$47,0)+(H9-I9)-(D9-E9) -> 0 | G9: =ROUND('INVEST ET FINANCEMENT'!F$47,0) -> 0 | H9: 0 | I9: =ROUND(E9+'INVEST ET FINANCEMENT'!F$47-'INVEST ET FINANCEMENT'!F$48,0) -> 0 | J9: =(D9-E9)+(F9-G9)-(H9-I9) -> 0
A10: 173060 | B10: Dettes de location-acquisition | C10: DB | D10: ='BALANCE 2026'!H10 -> 0 | E10: ='BALANCE 2026'!I10 -> 0 | F10: =ROUND('INVEST ET FINANCEMENT'!F$49,0) -> 0 | G10: =ROUND('INVEST ET FINANCEMENT'!F$49,0)+(D10-E10)-(H10-I10) -> 0 | H10: 0 | I10: =ROUND(E10-'INVEST ET FINANCEMENT'!F$49,0) -> 0 | J10: =(D10-E10)+(F10-G10)-(H10-I10) -> 0
A11: 196100 | B11: Provisions pour pensions et obligations similaires (IFC) | C11: DC | D11: ='BALANCE 2026'!H11 -> 0 | E11: ='BALANCE 2026'!I11 -> 33392488 | F11: =ROUND(HYPOTHESES!F$20,0)+(H11-I11)-(D11-E11) -> 0 | G11: =ROUND(HYPOTHESES!F$20,0) -> 6059296 | H11: 0 | I11: =ROUND(E11+HYPOTHESES!F$20,0) -> 39451784 | J11: =(D11-E11)+(F11-G11)-(H11-I11) -> 0
A12: 234100 | B12: Aménagements, agencements et installations techniques | C12: AL | D12: ='BALANCE 2026'!H12 -> 103601492 | E12: ='BALANCE 2026'!I12 -> 0 | F12: =ROUND('INVEST ET FINANCEMENT'!F$9,0) -> 0 | G12: =ROUND('INVEST ET FINANCEMENT'!F$9,0)+(D12-E12)-(H12-I12) -> 0 | H12: =ROUND(D12+'INVEST ET FINANCEMENT'!F$9,0) -> 103601492 | I12: 0 | J12: =(D12-E12)+(F12-G12)-(H12-I12) -> 0
A13: 241100 | B13: Matériel industriel | C13: AM | D13: ='BALANCE 2026'!H13 -> 343845268 | E13: ='BALANCE 2026'!I13 -> 0 | F13: =ROUND('INVEST ET FINANCEMENT'!F$10,0) -> 30000000 | G13: =ROUND('INVEST ET FINANCEMENT'!F$10,0)+(D13-E13)-(H13-I13) -> 0 | H13: =ROUND(D13+'INVEST ET FINANCEMENT'!F$10,0) -> 373845268 | I13: 0 | J13: =(D13-E13)+(F13-G13)-(H13-I13) -> 0
A14: 244100 | B14: Matériel de bureau | C14: AM | D14: ='BALANCE 2026'!H14 -> 9306956 | E14: ='BALANCE 2026'!I14 -> 0 | F14: =MAX(0,(H14-I14)-(D14-E14)) -> 0 | G14: =MAX(0,(D14-E14)-(H14-I14)) -> 0 | H14: =ROUND(D14,0) -> 9306956 | I14: 0 | J14: =(D14-E14)+(F14-G14)-(H14-I14) -> 0
A15: 244200 | B15: Matériel informatique | C15: AM | D15: ='BALANCE 2026'!H15 -> 18910459 | E15: ='BALANCE 2026'!I15 -> 0 | F15: =ROUND('INVEST ET FINANCEMENT'!F$11,0) -> 5000000 | G15: =ROUND('INVEST ET FINANCEMENT'!F$11,0)+(D15-E15)-(H15-I15) -> 0 | H15: =ROUND(D15+'INVEST ET FINANCEMENT'!F$11,0) -> 23910459 | I15: 0 | J15: =(D15-E15)+(F15-G15)-(H15-I15) -> 0
A16: 245100 | B16: Matériel automobile | C16: AN | D16: ='BALANCE 2026'!H16 -> 423638205 | E16: ='BALANCE 2026'!I16 -> 0 | F16: =ROUND('INVEST ET FINANCEMENT'!F$12,0) -> 0 | G16: =ROUND('INVEST ET FINANCEMENT'!F$12,0)+(D16-E16)-(H16-I16) -> 0 | H16: =ROUND(D16+'INVEST ET FINANCEMENT'!F$12,0) -> 423638205 | I16: 0 | J16: =(D16-E16)+(F16-G16)-(H16-I16) -> 0
A17: 245600 | B17: Matériel de transport en location-acquisition | C17: AN | D17: ='BALANCE 2026'!H17 -> 28619694 | E17: ='BALANCE 2026'!I17 -> 0 | F17: =MAX(0,(H17-I17)-(D17-E17)) -> 0 | G17: =MAX(0,(D17-E17)-(H17-I17)) -> 0 | H17: =ROUND(D17,0) -> 28619694 | I17: 0 | J17: =(D17-E17)+(F17-G17)-(H17-I17) -> 0
A18: 271800 | B18: Autres prêts et créances | C18: AS | D18: ='BALANCE 2026'!H18 -> 25000000 | E18: ='BALANCE 2026'!I18 -> 0 | F18: =MAX(0,(H18-I18)-(D18-E18)) -> 0 | G18: =MAX(0,(D18-E18)-(H18-I18)) -> 0 | H18: =ROUND(D18,0) -> 25000000 | I18: 0 | J18: =(D18-E18)+(F18-G18)-(H18-I18) -> 0
A19: 275100 | B19: Dépôts et cautionnements versés | C19: AS | D19: ='BALANCE 2026'!H19 -> 231420138 | E19: ='BALANCE 2026'!I19 -> 0 | F19: =ROUND('INVEST ET FINANCEMENT'!F$13,0) -> 0 | G19: =ROUND('INVEST ET FINANCEMENT'!F$13,0)+(D19-E19)-(H19-I19) -> 0 | H19: =ROUND(D19+'INVEST ET FINANCEMENT'!F$13,0) -> 231420138 | I19: 0 | J19: =(D19-E19)+(F19-G19)-(H19-I19) -> 0
A20: 283400 | B20: Amortissements des aménagements, agencements | C20: AL | D20: ='BALANCE 2026'!H20 -> 0 | E20: ='BALANCE 2026'!I20 -> 80502166 | F20: =ROUND('INVEST ET FINANCEMENT'!F$31,0)+(H20-I20)-(D20-E20) -> 0 | G20: =ROUND('INVEST ET FINANCEMENT'!F$31,0) -> 19282845 | H20: 0 | I20: =ROUND(E20+'INVEST ET FINANCEMENT'!F$31,0) -> 99785011 | J20: =(D20-E20)+(F20-G20)-(H20-I20) -> 0
A21: 284100 | B21: Amortissements du matériel et outillage | C21: AM | D21: ='BALANCE 2026'!H21 -> 0 | E21: ='BALANCE 2026'!I21 -> 135043749 | F21: =ROUND('INVEST ET FINANCEMENT'!F$34,0)+(H21-I21)-(D21-E21) -> 0 | G21: =ROUND('INVEST ET FINANCEMENT'!F$34,0) -> 56854932 | H21: 0 | I21: =ROUND(E21+'INVEST ET FINANCEMENT'!F$34,0) -> 191898681 | J21: =(D21-E21)+(F21-G21)-(H21-I21) -> 0
A22: 284400 | B22: Amortissements du matériel de bureau et informatique | C22: AM | D22: ='BALANCE 2026'!H22 -> 0 | E22: ='BALANCE 2026'!I22 -> 25717415 | F22: =ROUND('INVEST ET FINANCEMENT'!F$37,0)+(H22-I22)-(D22-E22) -> 0 | G22: =ROUND('INVEST ET FINANCEMENT'!F$37,0) -> 5000000 | H22: 0 | I22: =ROUND(E22+'INVEST ET FINANCEMENT'!F$37,0) -> 30717415 | J22: =(D22-E22)+(F22-G22)-(H22-I22) -> 0
A23: 284500 | B23: Amortissements du matériel de transport | C23: AN | D23: ='BALANCE 2026'!H23 -> 0 | E23: ='BALANCE 2026'!I23 -> 397825832 | F23: =ROUND('INVEST ET FINANCEMENT'!F$40,0)+(H23-I23)-(D23-E23) -> 0 | G23: =ROUND('INVEST ET FINANCEMENT'!F$40,0) -> 15958378 | H23: 0 | I23: =ROUND(E23+'INVEST ET FINANCEMENT'!F$40,0) -> 413784210 | J23: =(D23-E23)+(F23-G23)-(H23-I23) -> 0
A24: 401100 | B24: Fournisseurs | C24: DJ | D24: ='BALANCE 2026'!H24 -> 0 | E24: ='BALANCE 2026'!I24 -> 81595000 | F24: =ROUND(HYPOTHESES!F$49*(1+HYPOTHESES!F$10),0)+(H24-I24)-(D24-E24) -> 537023933 | G24: =ROUND(HYPOTHESES!F$49*(1+HYPOTHESES!F$10),0) -> 541103683 | H24: 0 | I24: =ROUND(HYPOTHESES!F$49*(1+HYPOTHESES!F$10)*HYPOTHESES!F$23/360,0) -> 85674750 | J24: =(D24-E24)+(F24-G24)-(H24-I24) -> 0
A25: 409100 | B25: Fournisseurs avances et accoptes ve | C25: BH | D25: ='BALANCE 2026'!H25 -> 0 | E25: ='BALANCE 2026'!I25 -> 0 | F25: =MAX(0,(H25-I25)-(D25-E25)) -> 0 | G25: =MAX(0,(D25-E25)-(H25-I25)) -> 0 | H25: =ROUND(D25,0) -> 0 | I25: =ROUND(E25,0) -> 0 | J25: =(D25-E25)+(F25-G25)-(H25-I25) -> 0
A26: 411100 | B26: Clients | C26: BI | D26: ='BALANCE 2026'!H26 -> 508573077 | E26: ='BALANCE 2026'!I26 -> 0 | F26: =ROUND(HYPOTHESES!F$42*(1+HYPOTHESES!F$10),0) -> 975840727 | G26: =ROUND(HYPOTHESES!F$42*(1+HYPOTHESES!F$10),0)+(D26-E26)-(H26-I26) -> 950412073 | H26: =ROUND(HYPOTHESES!F$42*(1+HYPOTHESES!F$10)*HYPOTHESES!F$22/360,0) -> 534001731 | I26: 0 | J26: =(D26-E26)+(F26-G26)-(H26-I26) -> 0
